Workbook

Sheet Config
A1: Parameter | B1: Value | C1: Description
A2: Rounding step | B2: 5e-06 | C2: ← Change this. Prices are rounded to the nearest multiple. Default 0.000005. Set to 0 for no rounding.
A3: Delta (%) | B3: 1 | C3: Geometric step per canonical tick, in percent.
A4: MAX_TICK | B4: 2600 | C4: Highest canonical tick index.
A5: Midpoint | B5: =B4/2 | C5: (derived) Half of MAX_TICK.

Sheet All Ticks
A1: Tick | B1: Raw Price | C1: Rounded Price | D1: Implied Rate (%) | E1: Lvl 0 (÷8) | F1: Lvl 1 (÷4) | G1: Lvl 2 (÷2) | H1: Lvl 3 (all) | I1: Finest Level | K1: Legend
A2: 0 | B2: =1/(1+(1+Config!$B$3/100)^(Config!$B$5-A2)) | C2: =IF(Config!$B$2=0,B2,ROUND(B2/Config!$B$2,0)*Config!$B$2) | D2: =IF(C2>0,(1/C2-1)*100,"∞") | E2: ✓ | F2: ✓ | G2: ✓ | H2: ✓ | I2: 0 | K2: Level 0 — every 8th tick (~8.3%)
A3: 1 | B3: =1/(1+(1+Config!$B$3/100)^(Config!$B$5-A3)) | C3: =IF(Config!$B$2=0,B3,ROUND(B3/Config!$B$2,0)*Config!$B$2) | D3: =IF(C3>0,(1/C3-1)*100,"∞") | H3: ✓ | I3: 3 | K3: Level 1 — every 4th tick (~4.1%)
A4: 2 | B4: =1/(1+(1+Config!$B$3/100)^(Config!$B$5-A4)) | C4: =IF(Config!$B$2=0,B4,ROUND(B4/Config!$B$2,0)*Config!$B$2) | D4: =IF(C4>0,(1/C4-1)*100,"∞") | G4: ✓ | H4: ✓ | I4: 2 | K4: Level 2 — every 2nd tick (~2.0%)
A5: 3 | B5: =1/(1+(1+Config!$B$3/100)^(Config!$B$5-A5)) | C5: =IF(Config!$B$2=0,B5,ROUND(B5/Config!$B$2,0)*Config!$B$2) | D5: =IF(C5>0,(1/C5-1)*100,"∞") | H5: ✓ | I5: 3 | K5: Level 3 — every tick (~1.0%)
A6: 4 | B6: =1/(1+(1+Config!$B$3/100)^(Config!$B$5-A6)) | C6: =IF(Config!$B$2=0,B6,ROUND(B6/Config!$B$2,0)*Config!$B$2) | D6: =IF(C6>0,(1/C6-1)*100,"∞") | F6: ✓ | G6: ✓ | H6: ✓ | I6: 1
A7: 5 | B7: =1/(1+(1+Config!$B$3/100)^(Config!$B$5-A7)) | C7: =IF(Config!$B$2=0,B7,ROUND(B7/Config!$B$2,0)*Config!$B$2) | D7: =IF(C7>0,(1/C7-1)*100,"∞") | H7: ✓ | I7: 3
A8: 6 | B8: =1/(1+(1+Config!$B$3/100)^(Config!$B$5-A8)) | C8: =IF(Config!$B$2=0,B8,ROUND(B8/Config!$B$2,0)*Config!$B$2) | D8: =IF(C8>0,(1/C8-1)*100,"∞") | G8: ✓ | H8: ✓ | I8: 2
A9: 7 | B9: =1/(1+(1+Config!$B$3/100)^(Config!$B$5-A9)) | C9: =IF(Config!$B$2=0,B9,ROUND(B9/Config!$B$2,0)*Config!$B$2) | D9: =IF(C9>0,(1/C9-1)*100,"∞") | H9: ✓ | I9: 3
A10: 8 | B10: =1/(1+(1+Config!$B$3/100)^(Config!$B$5-A10)) | C10: =IF(Config!$B$2=0,B10,ROUND(B10/Config!$B$2,0)*Config!$B$2) | D10: =IF(C10>0,(1/C10-1)*100,"∞") | E10: ✓ | F10: ✓ | G10: ✓ | H10: ✓ | I10: 0
A11: 9 | B11: =1/(1+(1+Config!$B$3/100)^(Config!$B$5-A11)) | C11: =IF(Config!$B$2=0,B11,ROUND(B11/Config!$B$2,0)*Config!$B$2) | D11: =IF(C11>0,(1/C11-1)*100,"∞") | H11: ✓ | I11: 3
A12: 10 | B12: =1/(1+(1+Config!$B$3/100)^(Config!$B$5-A12)) | C12: =IF(Config!$B$2=0,B12,ROUND(B12/Config!$B$2,0)*Config!$B$2) | D12: =IF(C12>0,(1/C12-1)*100,"∞") | G12: ✓ | H12: ✓ | I12: 2
A13: 11 | B13: =1/(1+(1+Config!$B$3/100)^(Config!$B$5-A13)) | C13: =IF(Config!$B$2=0,B13,ROUND(B13/Config!$B$2,0)*Config!$B$2) | D13: =IF(C13>0,(1/C13-1)*100,"∞") | H13: ✓ | I13: 3
A14: 12 | B14: =1/(1+(1+Config!$B$3/100)^(Config!$B$5-A14)) | C14: =IF(Config!$B$2=0,B14,ROUND(B14/Config!$B$2,0)*Config!$B$2) | D14: =IF(C14>0,(1/C14-1)*100,"∞") | F14: ✓ | G14: ✓ | H14: ✓ | I14: 1
A15: 13 | B15: =1/(1+(1+Config!$B$3/100)^(Config!$B$5-A15)) | C15: =IF(Config!$B$2=0,B15,ROUND(B15/Config!$B$2,0)*Config!$B$2) | D15: =IF(C15>0,(1/C15-1)*100,"∞") | H15: ✓ | I15: 3
A16: 14 | B16: =1/(1+(1+Config!$B$3/100)^(Config!$B$5-A16)) | C16: =IF(Config!$B$2=0,B16,ROUND(B16/Config!$B$2,0)*Config!$B$2) | D16: =IF(C16>0,(1/C16-1)*100,"∞") | G16: ✓ | H16: ✓ | I16: 2
A17: 15 | B17: =1/(1+(1+Config!$B$3/100)^(Config!$B$5-A17)) | C17: =IF(Config!$B$2=0,B17,ROUND(B17/Config!$B$2,0)*Config!$B$2) | D17: =IF(C17>0,(1/C17-1)*100,"∞") | H17: ✓ | I17: 3
A18: 16 | B18: =1/(1+(1+Config!$B$3/100)^(Config!$B$5-A18)) | C18: =IF(Config!$B$2=0,B18,ROUND(B18/Config!$B$2,0)*Config!$B$2) | D18: =IF(C18>0,(1/C18-1)*100,"∞") | E18: ✓ | F18: ✓ | G18: ✓ | H18: ✓ | I18: 0
A19: 17 | B19: =1/(1+(1+Config!$B$3/100)^(Config!$B$5-A19)) | C19: =IF(Config!$B$2=0,B19,ROUND(B19/Config!$B$2,0)*Config!$B$2) | D19: =IF(C19>0,(1/C19-1)*100,"∞") | H19: ✓ | I19: 3
A20: 18 | B20: =1/(1+(1+Config!$B$3/100)^(Config!$B$5-A20)) | C20: =IF(Config!$B$2=0,B20,ROUND(B20/Config!$B$2,0)*Config!$B$2) | D20: =IF(C20>0,(1/C20-1)*100,"∞") | G20: ✓ | H20: ✓ | I20: 2
A21: 19 | B21: =1/(1+(1+Config!$B$3/100)^(Config!$B$5-A21)) | C21: =IF(Config!$B$2=0,B21,ROUND(B21/Config!$B$2,0)*Config!$B$2) | D21: =IF(C21>0,(1/C21-1)*100,"∞") | H21: ✓ | I21: 3
A22: 20 | B22: =1/(1+(1+Config!$B$3/100)^(Config!$B$5-A22)) | C22: =IF(Config!$B$2=0,B22,ROUND(B22/Config!$B$2,0)*Config!$B$2) | D22: =IF(C22>0,(1/C22-1)*100,"∞") | F22: ✓ | G22: ✓ | H22: ✓ | I22: 1
A23: 21 | B23: =1/(1+(1+Config!$B$3/100)^(Config!$B$5-A23)) | C23: =IF(Config!$B$2=0,B23,ROUND(B23/Config!$B$2,0)*Config!$B$2) | D23: =IF(C23>0,(1/C23-1)*100,"∞") | H23: ✓ | I23: 3
A24: 22 | B24: =1/(1+(1+Config!$B$3/100)^(Config!$B$5-A24)) | C24: =IF(Config!$B$2=0,B24,ROUND(B24/Config!$B$2,0)*Config!$B$2) | D24: =IF(C24>0,(1/C24-1)*100,"∞") | G24: ✓ | H24: ✓ | I24: 2
A25: 23 | B25: =1/(1+(1+Config!$B$3/100)^(Config!$B$5-A25)) | C25: =IF(Config!$B$2=0,B25,ROUND(B25/Config!$B$2,0)*Config!$B$2) | D25: =IF(C25>0,(1/C25-1)*100,"∞") | H25: ✓ | I25: 3
A26: 24 | B26: =1/(1+(1+Config!$B$3/100)^(Config!$B$5-A26)) | C26: =IF(Config!$B$2=0,B26,ROUND(B26/Config!$B$2,0)*Config!$B$2) | D26: =IF(C26>0,(1/C26-1)*100,"∞") | E26: ✓ | F26: ✓ | G26: ✓ | H26: ✓ | I26: 0
A27: 25 | B27: =1/(1+(1+Config!$B$3/100)^(Config!$B$5-A27)) | C27: =IF(Config!$B$2=0,B27,ROUND(B27/Config!$B$2,0)*Config!$B$2) | D27: =IF(C27>0,(1/C27-1)*100,"∞") | H27: ✓ | I27: 3
A28: 26 | B28: =1/(1+(1+Config!$B$3/100)^(Config!$B$5-A28)) | C28: =IF(Config!$B$2=0,B28,ROUND(B28/Config!$B$2,0)*Config!$B$2) | D28: =IF(C28>0,(1/C28-1)*100,"∞") | G28: ✓ | H28: ✓ | I28: 2
A29: 27 | B29: =1/(1+(1+Config!$B$3/100)^(Config!$B$5-A29)) | C29: =IF(Config!$B$2=0,B29,ROUND(B29/Config!$B$2,0)*Config!$B$2) | D29: =IF(C29>0,(1/C29-1)*100,"∞") | H29: ✓ | I29: 3
A30: 28 | B30: =1/(1+(1+Config!$B$3/100)^(Config!$B$5-A30)) | C30: =IF(Config!$B$2=0,B30,ROUND(B30/Config!$B$2,0)*Config!$B$2) | D30: =IF(C30>0,(1/C30-1)*100,"∞") | F30: ✓ | G30: ✓ | H30: ✓ | I30: 1
A31: 29 | B31: =1/(1+(1+Config!$B$3/100)^(Config!$B$5-A31)) | C31: =IF(Config!$B$2=0,B31,ROUND(B31/Config!$B$2,0)*Config!$B$2) | D31: =IF(C31>0,(1/C31-1)*100,"∞") | H31: ✓ | I31: 3
A32: 30 | B32: =1/(1+(1+Config!$B$3/100)^(Config!$B$5-A32)) | C32: =IF(Config!$B$2=0,B32,ROUND(B32/Config!$B$2,0)*Config!$B$2) | D32: =IF(C32>0,(1/C32-1)*100,"∞") | G32: ✓ | H32: ✓ | I32: 2
A33: 31 | B33: =1/(1+(1+Config!$B$3/100)^(Config!$B$5-A33)) | C33: =IF(Config!$B$2=0,B33,ROUND(B33/Config!$B$2,0)*Config!$B$2) | D33: =IF(C33>0,(1/C33-1)*100,"∞") | H33: ✓ | I33: 3
A34: 32 | B34: =1/(1+(1+Config!$B$3/100)^(Config!$B$5-A34)) | C34: =IF(Config!$B$2=0,B34,ROUND(B34/Config!$B$2,0)*Config!$B$2) | D34: =IF(C34>0,(1/C34-1)*100,"∞") | E34: ✓ | F34: ✓ | G34: ✓ | H34: ✓ | I34: 0
A35: 33 | B35: =1/(1+(1+Config!$B$3/100)^(Config!$B$5-A35)) | C35: =IF(Config!$B$2=0,B35,ROUND(B35/Config!$B$2,0)*Config!$B$2) | D35: =IF(C35>0,(1/C35-1)*100,"∞") | H35: ✓ | I35: 3
A36: 34 | B36: =1/(1+(1+Config!$B$3/100)^(Config!$B$5-A36)) | C36: =IF(Config!$B$2=0,B36,ROUND(B36/Config!$B$2,0)*Config!$B$2) | D36: =IF(C36>0,(1/C36-1)*100,"∞") | G36: ✓ | H36: ✓ | I36: 2
A37: 35 | B37: =1/(1+(1+Config!$B$3/100)^(Config!$B$5-A37)) | C37: =IF(Config!$B$2=0,B37,ROUND(B37/Config!$B$2,0)*Config!$B$2) | D37: =IF(C37>0,(1/C37-1)*100,"∞") | H37: ✓ | I37: 3
A38: 36 | B38: =1/(1+(1+Config!$B$3/100)^(Config!$B$5-A38)) | C38: =IF(Config!$B$2=0,B38,ROUND(B38/Config!$B$2,0)*Config!$B$2) | D38: =IF(C38>0,(1/C38-1)*100,"∞") | F38: ✓ | G38: ✓ | H38: ✓ | I38: 1
A39: 37 | B39: =1/(1+(1+Config!$B$3/100)^(Config!$B$5-A39)) | C39: =IF(Config!$B$2=0,B39,ROUND(B39/Config!$B$2,0)*Config!$B$2) | D39: =IF(C39>0,(1/C39-1)*100,"∞") | H39: ✓ | I39: 3
A40: 38 | B40: =1/(1+(1+Config!$B$3/100)^(Config!$B$5-A40)) | C40: =IF(Config!$B$2=0,B40,ROUND(B40/Config!$B$2,0)*Config!$B$2) | D40: =IF(C40>0,(1/C40-1)*100,"∞") | G40: ✓ | H40: ✓ | I40: 2
...

Sheet Level 0 (÷8)
A1: Tick | B1: Raw Price | C1: Rounded Price | D1: Implied Rate (%) | E1: Rate Step vs Prev (%)
A2: 0 | B2: =1/(1+(1+Config!$B$3/100)^(Config!$B$5-A2)) | C2: =IF(Config!$B$2=0,B2,ROUND(B2/Config!$B$2,0)*Config!$B$2) | D2: =IF(C2>0,(1/C2-1)*100,"∞")
A3: 8 | B3: =1/(1+(1+Config!$B$3/100)^(Config!$B$5-A3)) | C3: =IF(Config!$B$2=0,B3,ROUND(B3/Config!$B$2,0)*Config!$B$2) | D3: =IF(C3>0,(1/C3-1)*100,"∞") | E3: =IF(AND(D2<>"∞",D3<>"∞",D3>0),(D2/D3-1)*100,"")
A4: 16 | B4: =1/(1+(1+Config!$B$3/100)^(Config!$B$5-A4)) | C4: =IF(Config!$B$2=0,B4,ROUND(B4/Config!$B$2,0)*Config!$B$2) | D4: =IF(C4>0,(1/C4-1)*100,"∞") | E4: =IF(AND(D3<>"∞",D4<>"∞",D4>0),(D3/D4-1)*100,"")
A5: 24 | B5: =1/(1+(1+Config!$B$3/100)^(Config!$B$5-A5)) | C5: =IF(Config!$B$2=0,B5,ROUND(B5/Config!$B$2,0)*Config!$B$2) | D5: =IF(C5>0,(1/C5-1)*100,"∞") | E5: =IF(AND(D4<>"∞",D5<>"∞",D5>0),(D4/D5-1)*100,"")
A6: 32 | B6: =1/(1+(1+Config!$B$3/100)^(Config!$B$5-A6)) | C6: =IF(Config!$B$2=0,B6,ROUND(B6/Config!$B$2,0)*Config!$B$2) | D6: =IF(C6>0,(1/C6-1)*100,"∞") | E6: =IF(AND(D5<>"∞",D6<>"∞",D6>0),(D5/D6-1)*100,"")
A7: 40 | B7: =1/(1+(1+Config!$B$3/100)^(Config!$B$5-A7)) | C7: =IF(Config!$B$2=0,B7,ROUND(B7/Config!$B$2,0)*Config!$B$2) | D7: =IF(C7>0,(1/C7-1)*100,"∞") | E7: =IF(AND(D6<>"∞",D7<>"∞",D7>0),(D6/D7-1)*100,"")
A8: 48 | B8: =1/(1+(1+Config!$B$3/100)^(Config!$B$5-A8)) | C8: =IF(Config!$B$2=0,B8,ROUND(B8/Config!$B$2,0)*Config!$B$2) | D8: =IF(C8>0,(1/C8-1)*100,"∞") | E8: =IF(AND(D7<>"∞",D8<>"∞",D8>0),(D7/D8-1)*100,"")
A9: 56 | B9: =1/(1+(1+Config!$B$3/100)^(Config!$B$5-A9)) | C9: =IF(Config!$B$2=0,B9,ROUND(B9/Config!$B$2,0)*Config!$B$2) | D9: =IF(C9>0,(1/C9-1)*100,"∞") | E9: =IF(AND(D8<>"∞",D9<>"∞",D9>0),(D8/D9-1)*100,"")
A10: 64 | B10: =1/(1+(1+Config!$B$3/100)^(Config!$B$5-A10)) | C10: =IF(Config!$B$2=0,B10,ROUND(B10/Config!$B$2,0)*Config!$B$2) | D10: =IF(C10>0,(1/C10-1)*100,"∞") | E10: =IF(AND(D9<>"∞",D10<>"∞",D10>0),(D9/D10-1)*100,"")
A11: 72 | B11: =1/(1+(1+Config!$B$3/100)^(Config!$B$5-A11)) | C11: =IF(Config!$B$2=0,B11,ROUND(B11/Config!$B$2,0)*Config!$B$2) | D11: =IF(C11>0,(1/C11-1)*100,"∞") | E11: =IF(AND(D10<>"∞",D11<>"∞",D11>0),(D10/D11-1)*100,"")
A12: 80 | B12: =1/(1+(1+Config!$B$3/100)^(Config!$B$5-A12)) | C12: =IF(Config!$B$2=0,B12,ROUND(B12/Config!$B$2,0)*Config!$B$2) | D12: =IF(C12>0,(1/C12-1)*100,"∞") | E12: =IF(AND(D11<>"∞",D12<>"∞",D12>0),(D11/D12-1)*100,"")
A13: 88 | B13: =1/(1+(1+Config!$B$3/100)^(Config!$B$5-A13)) | C13: =IF(Config!$B$2=0,B13,ROUND(B13/Config!$B$2,0)*Config!$B$2) | D13: =IF(C13>0,(1/C13-1)*100,"∞") | E13: =IF(AND(D12<>"∞",D13<>"∞",D13>0),(D12/D13-1)*100,"")
A14: 96 | B14: =1/(1+(1+Config!$B$3/100)^(Config!$B$5-A14)) | C14: =IF(Config!$B$2=0,B14,ROUND(B14/Config!$B$2,0)*Config!$B$2) | D14: =IF(C14>0,(1/C14-1)*100,"∞") | E14: =IF(AND(D13<>"∞",D14<>"∞",D14>0),(D13/D14-1)*100,"")
... A327: 2600 | B327: =1/(1+(1+Config!$B$3/100)^(Config!$B$5-A327)) | C327: =IF(Config!$B$2=0,B327,ROUND(B327/Config!$B$2,0)*Config!$B$2) | D327: =IF(C327>0,(1/C327-1)*100,"∞") | E327: =IF(AND(D326<>"∞",D327<>"∞",D327>0),(D326/D327-1)*100,"")

Sheet Level 1 (÷4)
A1: Tick | B1: Raw Price | C1: Rounded Price | D1: Implied Rate (%) | E1: Rate Step vs Prev (%)
A2: 0 | B2: =1/(1+(1+Config!$B$3/100)^(Config!$B$5-A2)) | C2: =IF(Config!$B$2=0,B2,ROUND(B2/Config!$B$2,0)*Config!$B$2) | D2: =IF(C2>0,(1/C2-1)*100,"∞")
A3: 4 | B3: =1/(1+(1+Config!$B$3/100)^(Config!$B$5-A3)) | C3: =IF(Config!$B$2=0,B3,ROUND(B3/Config!$B$2,0)*Config!$B$2) | D3: =IF(C3>0,(1/C3-1)*100,"∞") | E3: =IF(AND(D2<>"∞",D3<>"∞",D3>0),(D2/D3-1)*100,"")
A4: 8 | B4: =1/(1+(1+Config!$B$3/100)^(Config!$B$5-A4)) | C4: =IF(Config!$B$2=0,B4,ROUND(B4/Config!$B$2,0)*Config!$B$2) | D4: =IF(C4>0,(1/C4-1)*100,"∞") | E4: =IF(AND(D3<>"∞",D4<>"∞",D4>0),(D3/D4-1)*100,"")
A5: 12 | B5: =1/(1+(1+Config!$B$3/100)^(Config!$B$5-A5)) | C5: =IF(Config!$B$2=0,B5,ROUND(B5/Config!$B$2,0)*Config!$B$2) | D5: =IF(C5>0,(1/C5-1)*100,"∞") | E5: =IF(AND(D4<>"∞",D5<>"∞",D5>0),(D4/D5-1)*100,"")
A6: 16 | B6: =1/(1+(1+Config!$B$3/100)^(Config!$B$5-A6)) | C6: =IF(Config!$B$2=0,B6,ROUND(B6/Config!$B$2,0)*Config!$B$2) | D6: =IF(C6>0,(1/C6-1)*100,"∞") | E6: =IF(AND(D5<>"∞",D6<>"∞",D6>0),(D5/D6-1)*100,"")
A7: 20 | B7: =1/(1+(1+Config!$B$3/100)^(Config!$B$5-A7)) | C7: =IF(Config!$B$2=0,B7,ROUND(B7/Config!$B$2,0)*Config!$B$2) | D7: =IF(C7>0,(1/C7-1)*100,"∞") | E7: =IF(AND(D6<>"∞",D7<>"∞",D7>0),(D6/D7-1)*100,"")
A8: 24 | B8: =1/(1+(1+Config!$B$3/100)^(Config!$B$5-A8)) | C8: =IF(Config!$B$2=0,B8,ROUND(B8/Config!$B$2,0)*Config!$B$2) | D8: =IF(C8>0,(1/C8-1)*100,"∞") | E8: =IF(AND(D7<>"∞",D8<>"∞",D8>0),(D7/D8-1)*100,"")
A9: 28 | B9: =1/(1+(1+Config!$B$3/100)^(Config!$B$5-A9)) | C9: =IF(Config!$B$2=0,B9,ROUND(B9/Config!$B$2,0)*Config!$B$2) | D9: =IF(C9>0,(1/C9-1)*100,"∞") | E9: =IF(AND(D8<>"∞",D9<>"∞",D9>0),(D8/D9-1)*100,"")
A10: 32 | B10: =1/(1+(1+Config!$B$3/100)^(Config!$B$5-A10)) | C10: =IF(Config!$B$2=0,B10,ROUND(B10/Config!$B$2,0)*Config!$B$2) | D10: =IF(C10>0,(1/C10-1)*100,"∞") | E10: =IF(AND(D9<>"∞",D10<>"∞",D10>0),(D9/D10-1)*100,"")
A11: 36 | B11: =1/(1+(1+Config!$B$3/100)^(Config!$B$5-A11)) | C11: =IF(Config!$B$2=0,B11,ROUND(B11/Config!$B$2,0)*Config!$B$2) | D11: =IF(C11>0,(1/C11-1)*100,"∞") | E11: =IF(AND(D10<>"∞",D11<>"∞",D11>0),(D10/D11-1)*100,"")
A12: 40 | B12: =1/(1+(1+Config!$B$3/100)^(Config!$B$5-A12)) | C12: =IF(Config!$B$2=0,B12,ROUND(B12/Config!$B$2,0)*Config!$B$2) | D12: =IF(C12>0,(1/C12-1)*100,"∞") | E12: =IF(AND(D11<>"∞",D12<>"∞",D12>0),(D11/D12-1)*100,"")
A13: 44 | B13: =1/(1+(1+Config!$B$3/100)^(Config!$B$5-A13)) | C13: =IF(Config!$B$2=0,B13,ROUND(B13/Config!$B$2,0)*Config!$B$2) | D13: =IF(C13>0,(1/C13-1)*100,"∞") | E13: =IF(AND(D12<>"∞",D13<>"∞",D13>0),(D12/D13-1)*100,"")
A14: 48 | B14: =1/(1+(1+Config!$B$3/100)^(Config!$B$5-A14)) | C14: =IF(Config!$B$2=0,B14,ROUND(B14/Config!$B$2,0)*Config!$B$2) | D14: =IF(C14>0,(1/C14-1)*100,"∞") | E14: =IF(AND(D13<>"∞",D14<>"∞",D14>0),(D13/D14-1)*100,"")
... A652: 2600 | B652: =1/(1+(1+Config!$B$3/100)^(Config!$B$5-A652)) | C652: =IF(Config!$B$2=0,B652,ROUND(B652/Config!$B$2,0)*Config!$B$2) | D652: =IF(C652>0,(1/C652-1)*100,"∞") | E652: =IF(AND(D651<>"∞",D652<>"∞",D652>0),(D651/D652-1)*100,"")

Sheet Level 2 (÷2)
A1: Tick | B1: Raw Price | C1: Rounded Price | D1: Implied Rate (%) | E1: Rate Step vs Prev (%)
A2: 0 | B2: =1/(1+(1+Config!$B$3/100)^(Config!$B$5-A2)) | C2: =IF(Config!$B$2=0,B2,ROUND(B2/Config!$B$2,0)*Config!$B$2) | D2: =IF(C2>0,(1/C2-1)*100,"∞")
A3: 2 | B3: =1/(1+(1+Config!$B$3/100)^(Config!$B$5-A3)) | C3: =IF(Config!$B$2=0,B3,ROUND(B3/Config!$B$2,0)*Config!$B$2) | D3: =IF(C3>0,(1/C3-1)*100,"∞") | E3: =IF(AND(D2<>"∞",D3<>"∞",D3>0),(D2/D3-1)*100,"")
A4: 4 | B4: =1/(1+(1+Config!$B$3/100)^(Config!$B$5-A4)) | C4: =IF(Config!$B$2=0,B4,ROUND(B4/Config!$B$2,0)*Config!$B$2) | D4: =IF(C4>0,(1/C4-1)*100,"∞") | E4: =IF(AND(D3<>"∞",D4<>"∞",D4>0),(D3/D4-1)*100,"")
A5: 6 | B5: =1/(1+(1+Config!$B$3/100)^(Config!$B$5-A5)) | C5: =IF(Config!$B$2=0,B5,ROUND(B5/Config!$B$2,0)*Config!$B$2) | D5: =IF(C5>0,(1/C5-1)*100,"∞") | E5: =IF(AND(D4<>"∞",D5<>"∞",D5>0),(D4/D5-1)*100,"")
A6: 8 | B6: =1/(1+(1+Config!$B$3/100)^(Config!$B$5-A6)) | C6: =IF(Config!$B$2=0,B6,ROUND(B6/Config!$B$2,0)*Config!$B$2) | D6: =IF(C6>0,(1/C6-1)*100,"∞") | E6: =IF(AND(D5<>"∞",D6<>"∞",D6>0),(D5/D6-1)*100,"")
A7: 10 | B7: =1/(1+(1+Config!$B$3/100)^(Config!$B$5-A7)) | C7: =IF(Config!$B$2=0,B7,ROUND(B7/Config!$B$2,0)*Config!$B$2) | D7: =IF(C7>0,(1/C7-1)*100,"∞") | E7: =IF(AND(D6<>"∞",D7<>"∞",D7>0),(D6/D7-1)*100,"")
A8: 12 | B8: =1/(1+(1+Config!$B$3/100)^(Config!$B$5-A8)) | C8: =IF(Config!$B$2=0,B8,ROUND(B8/Config!$B$2,0)*Config!$B$2) | D8: =IF(C8>0,(1/C8-1)*100,"∞") | E8: =IF(AND(D7<>"∞",D8<>"∞",D8>0),(D7/D8-1)*100,"")
A9: 14 | B9: =1/(1+(1+Config!$B$3/100)^(Config!$B$5-A9)) | C9: =IF(Config!$B$2=0,B9,ROUND(B9/Config!$B$2,0)*Config!$B$2) | D9: =IF(C9>0,(1/C9-1)*100,"∞") | E9: =IF(AND(D8<>"∞",D9<>"∞",D9>0),(D8/D9-1)*100,"")
A10: 16 | B10: =1/(1+(1+Config!$B$3/100)^(Config!$B$5-A10)) | C10: =IF(Config!$B$2=0,B10,ROUND(B10/Config!$B$2,0)*Config!$B$2) | D10: =IF(C10>0,(1/C10-1)*100,"∞") | E10: =IF(AND(D9<>"∞",D10<>"∞",D10>0),(D9/D10-1)*100,"")
A11: 18 | B11: =1/(1+(1+Config!$B$3/100)^(Config!$B$5-A11)) | C11: =IF(Config!$B$2=0,B11,ROUND(B11/Config!$B$2,0)*Config!$B$2) | D11: =IF(C11>0,(1/C11-1)*100,"∞") | E11: =IF(AND(D10<>"∞",D11<>"∞",D11>0),(D10/D11-1)*100,"")
A12: 20 | B12: =1/(1+(1+Config!$B$3/100)^(Config!$B$5-A12)) | C12: =IF(Config!$B$2=0,B12,ROUND(B12/Config!$B$2,0)*Config!$B$2) | D12: =IF(C12>0,(1/C12-1)*100,"∞") | E12: =IF(AND(D11<>"∞",D12<>"∞",D12>0),(D11/D12-1)*100,"")
A13: 22 | B13: =1/(1+(1+Config!$B$3/100)^(Config!$B$5-A13)) | C13: =IF(Config!$B$2=0,B13,ROUND(B13/Config!$B$2,0)*Config!$B$2) | D13: =IF(C13>0,(1/C13-1)*100,"∞") | E13: =IF(AND(D12<>"∞",D13<>"∞",D13>0),(D12/D13-1)*100,"")
A14: 24 | B14: =1/(1+(1+Config!$B$3/100)^(Config!$B$5-A14)) | C14: =IF(Config!$B$2=0,B14,ROUND(B14/Config!$B$2,0)*Config!$B$2) | D14: =IF(C14>0,(1/C14-1)*100,"∞") | E14: =IF(AND(D13<>"∞",D14<>"∞",D14>0),(D13/D14-1)*100,"")
... A1302: 2600 | B1302: =1/(1+(1+Config!$B$3/100)^(Config!$B$5-A1302)) | C1302: =IF(Config!$B$2=0,B1302,ROUND(B1302/Config!$B$2,0)*Config!$B$2) | D1302: =IF(C1302>0,(1/C1302-1)*100,"∞") | E1302: =IF(AND(D1301<>"∞",D1302<>"∞",D1302>0),(D1301/D1302-1)*100,"")

Sheet Level 3 (all)
A1: Tick | B1: Raw Price | C1: Rounded Price | D1: Implied Rate (%) | E1: Rate Step vs Prev (%)
A2: 0 | B2: =1/(1+(1+Config!$B$3/100)^(Config!$B$5-A2)) | C2: =IF(Config!$B$2=0,B2,ROUND(B2/Config!$B$2,0)*Config!$B$2) | D2: =IF(C2>0,(1/C2-1)*100,"∞")
A3: 1 | B3: =1/(1+(1+Config!$B$3/100)^(Config!$B$5-A3)) | C3: =IF(Config!$B$2=0,B3,ROUND(B3/Config!$B$2,0)*Config!$B$2) | D3: =IF(C3>0,(1/C3-1)*100,"∞") | E3: =IF(AND(D2<>"∞",D3<>"∞",D3>0),(D2/D3-1)*100,"")
A4: 2 | B4: =1/(1+(1+Config!$B$3/100)^(Config!$B$5-A4)) | C4: =IF(Config!$B$2=0,B4,ROUND(B4/Config!$B$2,0)*Config!$B$2) | D4: =IF(C4>0,(1/C4-1)*100,"∞") | E4: =IF(AND(D3<>"∞",D4<>"∞",D4>0),(D3/D4-1)*100,"")
A5: 3 | B5: =1/(1+(1+Config!$B$3/100)^(Config!$B$5-A5)) | C5: =IF(Config!$B$2=0,B5,ROUND(B5/Config!$B$2,0)*Config!$B$2) | D5: =IF(C5>0,(1/C5-1)*100,"∞") | E5: =IF(AND(D4<>"∞",D5<>"∞",D5>0),(D4/D5-1)*100,"")
A6: 4 | B6: =1/(1+(1+Config!$B$3/100)^(Config!$B$5-A6)) | C6: =IF(Config!$B$2=0,B6,ROUND(B6/Config!$B$2,0)*Config!$B$2) | D6: =IF(C6>0,(1/C6-1)*100,"∞") | E6: =IF(AND(D5<>"∞",D6<>"∞",D6>0),(D5/D6-1)*100,"")
A7: 5 | B7: =1/(1+(1+Config!$B$3/100)^(Config!$B$5-A7)) | C7: =IF(Config!$B$2=0,B7,ROUND(B7/Config!$B$2,0)*Config!$B$2) | D7: =IF(C7>0,(1/C7-1)*100,"∞") | E7: =IF(AND(D6<>"∞",D7<>"∞",D7>0),(D6/D7-1)*100,"")
A8: 6 | B8: =1/(1+(1+Config!$B$3/100)^(Config!$B$5-A8)) | C8: =IF(Config!$B$2=0,B8,ROUND(B8/Config!$B$2,0)*Config!$B$2) | D8: =IF(C8>0,(1/C8-1)*100,"∞") | E8: =IF(AND(D7<>"∞",D8<>"∞",D8>0),(D7/D8-1)*100,"")
A9: 7 | B9: =1/(1+(1+Config!$B$3/100)^(Config!$B$5-A9)) | C9: =IF(Config!$B$2=0,B9,ROUND(B9/Config!$B$2,0)*Config!$B$2) | D9: =IF(C9>0,(1/C9-1)*100,"∞") | E9: =IF(AND(D8<>"∞",D9<>"∞",D9>0),(D8/D9-1)*100,"")
A10: 8 | B10: =1/(1+(1+Config!$B$3/100)^(Config!$B$5-A10)) | C10: =IF(Config!$B$2=0,B10,ROUND(B10/Config!$B$2,0)*Config!$B$2) | D10: =IF(C10>0,(1/C10-1)*100,"∞") | E10: =IF(AND(D9<>"∞",D10<>"∞",D10>0),(D9/D10-1)*100,"")
A11: 9 | B11: =1/(1+(1+Config!$B$3/100)^(Config!$B$5-A11)) | C11: =IF(Config!$B$2=0,B11,ROUND(B11/Config!$B$2,0)*Config!$B$2) | D11: =IF(C11>0,(1/C11-1)*100,"∞") | E11: =IF(AND(D10<>"∞",D11<>"∞",D11>0),(D10/D11-1)*100,"")
A12: 10 | B12: =1/(1+(1+Config!$B$3/100)^(Config!$B$5-A12)) | C12: =IF(Config!$B$2=0,B12,ROUND(B12/Config!$B$2,0)*Config!$B$2) | D12: =IF(C12>0,(1/C12-1)*100,"∞") | E12: =IF(AND(D11<>"∞",D12<>"∞",D12>0),(D11/D12-1)*100,"")
A13: 11 | B13: =1/(1+(1+Config!$B$3/100)^(Config!$B$5-A13)) | C13: =IF(Config!$B$2=0,B13,ROUND(B13/Config!$B$2,0)*Config!$B$2) | D13: =IF(C13>0,(1/C13-1)*100,"∞") | E13: =IF(AND(D12<>"∞",D13<>"∞",D13>0),(D12/D13-1)*100,"")
A14: 12 | B14: =1/(1+(1+Config!$B$3/100)^(Config!$B$5-A14)) | C14: =IF(Config!$B$2=0,B14,ROUND(B14/Config!$B$2,0)*Config!$B$2) | D14: =IF(C14>0,(1/C14-1)*100,"∞") | E14: =IF(AND(D13<>"∞",D14<>"∞",D14>0),(D13/D14-1)*100,"")
... A2602: 2600 | B2602: =1/(1+(1+Config!$B$3/100)^(Config!$B$5-A2602)) | C2602: =IF(Config!$B$2=0,B2602,ROUND(B2602/Config!$B$2,0)*Config!$B$2) | D2602: =IF(C2602>0,(1/C2602-1)*100,"∞") | E2602: =IF(AND(D2601<>"∞",D2602<>"∞",D2602>0),(D2601/D2602-1)*100,"")
